<?xml version="1.0" encoding="utf-8"?>
<!-- This URDF was automatically created by SolidWorks to URDF Exporter! Originally created by Stephen Brawner (brawner@gmail.com) 
     Commit Version: 1.6.0-4-g7f85cfe  Build Version: 1.6.7995.38578
     For more information, please see http://wiki.ros.org/sw_urdf_exporter -->
<robot
  name="robotic_arm">
  <link
    name="base_link">
    <inertial>
      <origin
        xyz="0.690918199012026 0.905986463170299 1.31818064426375"
        rpy="0 0 0" />
      <mass
        value="0.0953444546366154" />
      <inertia
        ixx="2.6536038073633E-05"
        ixy="1.32399943739737E-07"
        ixz="-1.95760719485948E-08"
        iyy="5.70826120419313E-05"
        iyz="1.60400346152967E-07"
        izz="5.93899507525617E-05" />
    </inertial>
    <visual>
      <origin
        xyz="0 0 0"
        rpy="0 0 0" />
      <geometry>
        <mesh
          filename="package://robotic_arm/meshes/base_link.STL" />
      </geometry>
      <material
        name="">
        <color
          rgba="0.752941176470588 0.752941176470588 0.752941176470588 1" />
      </material>
    </visual>
    <collision>
      <origin
        xyz="0 0 0"
        rpy="0 0 0" />
      <geometry>
        <mesh
          filename="package://robotic_arm/meshes/base_link.STL" />
      </geometry>
    </collision>
  </link>
  <link
    name="link_1">
    <inertial>
      <origin
        xyz="-0.00834673768467264 0.0592848892675473 -0.0104318358334772"
        rpy="0 0 0" />
      <mass
        value="0.0465317343320066" />
      <inertia
        ixx="1.28967179945359E-05"
        ixy="-1.1547621249523E-07"
        ixz="-2.00612048044345E-06"
        iyy="1.41046479661861E-05"
        iyz="1.10209138101129E-07"
        izz="1.28042688802891E-05" />
    </inertial>
    <visual>
      <origin
        xyz="0 0 0"
        rpy="0 0 0" />
      <geometry>
        <mesh
          filename="package://robotic_arm/meshes/link_1.STL" />
      </geometry>
      <material
        name="">
        <color
          rgba="0.752941176470588 0.752941176470588 0.752941176470588 1" />
      </material>
    </visual>
    <collision>
      <origin
        xyz="0 0 0"
        rpy="0 0 0" />
      <geometry>
        <mesh
          filename="package://robotic_arm/meshes/link_1.STL" />
      </geometry>
    </collision>
  </link>
  <joint
    name="joint_1"
    type="continuous">
    <origin
      xyz="0.681512899942898 -1.31957371207269 0.9106277233023"
      rpy="1.57079632679489 0 2.38986902292884" />
    <parent
      link="base_link" />
    <child
      link="link_1" />
    <axis
      xyz="0 1 0" />
  </joint>
  <link
    name="link_2">
    <inertial>
      <origin
        xyz="-0.00411555735884339 -0.049078206685365 0.0151869177878514"
        rpy="0 0 0" />
      <mass
        value="0.0196331437668373" />
      <inertia
        ixx="8.60828290164031E-06"
        ixy="-6.25849778546438E-07"
        ixz="-2.65465712344999E-06"
        iyy="1.03763652187751E-05"
        iyz="1.48452113083845E-06"
        izz="1.38316237542642E-05" />
    </inertial>
    <visual>
      <origin
        xyz="0 0 0"
        rpy="0 0 0" />
      <geometry>
        <mesh
          filename="package://robotic_arm/meshes/link_2.STL" />
      </geometry>
      <material
        name="">
        <color
          rgba="0.752941176470588 0.752941176470588 0.752941176470588 1" />
      </material>
    </visual>
    <collision>
      <origin
        xyz="0 0 0"
        rpy="0 0 0" />
      <geometry>
        <mesh
          filename="package://robotic_arm/meshes/link_2.STL" />
      </geometry>
    </collision>
  </link>
  <joint
    name="joint_2"
    type="continuous">
    <origin
      xyz="-0.0138083245935132 0.0680000000000357 -0.0144682470230319"
      rpy="0.244836805062138 -0.375384253365743 -3.01423665910926" />
    <parent
      link="link_1" />
    <child
      link="link_2" />
    <axis
      xyz="0.920715361532491 0.00279090919548123 0.390224850392638" />
  </joint>
  <link
    name="link_3">
    <inertial>
      <origin
        xyz="-0.0044466549163481 0.0223202695435483 -0.0051826332775049"
        rpy="0 0 0" />
      <mass
        value="0.0527193093583245" />
      <inertia
        ixx="1.35233138780833E-05"
        ixy="-6.51337467091475E-07"
        ixz="-2.45290637988036E-06"
        iyy="1.23208076940951E-05"
        iyz="1.80348552434389E-06"
        izz="1.78382592044603E-05" />
    </inertial>
    <visual>
      <origin
        xyz="0 0 0"
        rpy="0 0 0" />
      <geometry>
        <mesh
          filename="package://robotic_arm/meshes/link_3.STL" />
      </geometry>
      <material
        name="">
        <color
          rgba="0.752941176470588 0.752941176470588 0.752941176470588 1" />
      </material>
    </visual>
    <collision>
      <origin
        xyz="0 0 0"
        rpy="0 0 0" />
      <geometry>
        <mesh
          filename="package://robotic_arm/meshes/link_3.STL" />
      </geometry>
    </collision>
  </link>
  <joint
    name="joint_3"
    type="continuous">
    <origin
      xyz="-0.0119074417180245 -0.0981728744550843 0.0287975674968496"
      rpy="0.666909771133124 0.72745528612343 -2.87911848216658" />
    <parent
      link="link_2" />
    <child
      link="link_3" />
    <axis
      xyz="0.920648187108123 0.00215985289631251 0.39038730846429" />
  </joint>
  <link
    name="link_4">
    <inertial>
      <origin
        xyz="0.0006796801836913 0.0122665484090065 0.0211158228951782"
        rpy="0 0 0" />
      <mass
        value="0.0734303248905977" />
      <inertia
        ixx="1.38233645920986E-05"
        ixy="8.61051492964438E-07"
        ixz="-2.17371806113922E-06"
        iyy="1.3932561843694E-05"
        iyz="-2.30776403602052E-06"
        izz="1.9039071365358E-05" />
    </inertial>
    <visual>
      <origin
        xyz="0 0 0"
        rpy="0 0 0" />
      <geometry>
        <mesh
          filename="package://robotic_arm/meshes/link_4.STL" />
      </geometry>
      <material
        name="">
        <color
          rgba="0.752941176470588 0.752941176470588 0.752941176470588 1" />
      </material>
    </visual>
    <collision>
      <origin
        xyz="0 0 0"
        rpy="0 0 0" />
      <geometry>
        <mesh
          filename="package://robotic_arm/meshes/link_4.STL" />
      </geometry>
    </collision>
  </link>
  <joint
    name="joint_4"
    type="continuous">
    <origin
      xyz="0.00878557193452059 0.0942863948809806 -0.0213160274783319"
      rpy="2.98177224561093 0.0793264831605607 -3.13671933164858" />
    <parent
      link="link_3" />
    <child
      link="link_4" />
    <axis
      xyz="0.951231015101866 -0.0451134015264731 0.305162803944034" />
  </joint>
  <link
    name="end_effector">
    <inertial>
      <origin
        xyz="0.00177854814604139 0.0234331501592275 0.0505371369748944"
        rpy="0 0 0" />
      <mass
        value="0.0505964546832365" />
      <inertia
        ixx="9.05047696167065E-06"
        ixy="-5.23352350323484E-07"
        ixz="4.15252288647753E-07"
        iyy="8.61341699943017E-06"
        iyz="1.67063430643563E-06"
        izz="8.59379706262438E-06" />
    </inertial>
    <visual>
      <origin
        xyz="0 0 0"
        rpy="0 0 0" />
      <geometry>
        <mesh
          filename="package://robotic_arm/meshes/end_effector.STL" />
      </geometry>
      <material
        name="">
        <color
          rgba="0.752941176470588 0.752941176470588 0.752941176470588 1" />
      </material>
    </visual>
    <collision>
      <origin
        xyz="0 0 0"
        rpy="0 0 0" />
      <geometry>
        <mesh
          filename="package://robotic_arm/meshes/end_effector.STL" />
      </geometry>
    </collision>
  </link>
  <joint
    name="end_effector_joint"
    type="continuous">
    <origin
      xyz="0.00668895775777986 0.015904071986752 0.0405109050654748"
      rpy="2.00026591436005 0.0503809083594157 -3.01899503858886" />
    <parent
      link="link_4" />
    <child
      link="end_effector" />
    <axis
      xyz="0.0765333432788003 -0.713482347733641 -0.696480858917932" />
  </joint>
</robot>